Workbook

Sheet FINAL MODEL
A1: Macroeconomic Performance & Stability Index for South Asian countries (2023) for Industrial Sector
A4: S. no | B4: Variables | C4: Weight
A5: 1 | B5: GDP growth | C5: 0.09 | E5: COUNTRIES | F5: Index score | G5: Rank | H5: Percentile
A6: 2 | B6: Inflation | C6: 0.07 | E6: India | F6: 0.69143718 | G6: 1 | H6: 1
A7: 3 | B7: Gross domestic savings | C7: 0.08 | E7: Maldives | F7: 0.63958596 | G7: 2 | H7: 0.92857143
A8: 4 | B8: Age dependency ratio | C8: 0.08 | E8: Bhutan | F8: 0.54538493 | G8: 3 | H8: 0.85714286
A9: 5 | B9: Control of Corruption | C9: 0.09 | E9: Bangladesh | F9: 0.5358522 | G9: 4 | H9: 0.78571429
A10: 6 | B10: Employment in industry | C10: 0.1 | E10: Sri Lanka | F10: 0.39677137 | G10: 5 | H10: 0.71428571
A11: 7 | B11: Industry (including construction) | C11: 0.12 | E11: Nepal | F11: 0.2685878 | G11: 6 | H11: 0.64285714
A12: 8 | B12: Political Stability and Absence of Violence/Terrorism | C12: 0.09 | E12: Pakistan | F12: 0.18682971 | G12: 7 | H12: 0.57142857
A13: 9 | B13: Access to electricity | C13: 0.1
A14: 10 | B14: Gross capital formation | C14: 0.1
A15: 11 | B15: Population density (people per sq. km of land area) | C15: 0.08
B17: TOTAL | C17: =SUM(C5:C15) -> 1

Sheet NORMALIZED DATA
A1: Macroeconomic Performance & Stability Index for South Asian countries (2023)
A3: S. no | B3: Variables | C3: Weight | E3: COUNTRIES | F3: GDP growth | G3: Inflation | H3: Gross domestic savings | I3: Age dependency ratio | J3: Control of Corruption | K3: Employment in industry | L3: Industry (including construction) | M3: Political Stability and Absence of Violence/Terrorism | N3: Access to electricity | O3: Gross capital formation | P3: Population density (people per sq. km of land area) | Q3: Index score | R3: Rank | S3: Percentile | T3: score
A4: 1 | B4: GDP growth | C4: 0.08 | E4: Maldives | F4: =_xlfn.XLOOKUP(E4,DATA!$A$4:$A$11,DATA!$C$4:$C$11) -> 0.67331511 | G4: =_xlfn.XLOOKUP($E4,DATA!$A$4:$A$11,DATA!$E$4:$E$11) -> 1 | H4: =_xlfn.XLOOKUP($E4,DATA!$A$4:$A$11,DATA!$G$4:$G$11) -> 1 | I4: =_xlfn.XLOOKUP(E4,DATA!$A$5:$A$11,DATA!$I$5:$I$11) -> 1 | J4: =_xlfn.XLOOKUP(E4,DATA!$A$5:$A$11,DATA!$K$5:$K$11) -> 0.32716051 | K4: =_xlfn.XLOOKUP(E4,DATA!$A$5:$A$11,DATA!$M$5:$M$11) -> 0.87501887 | L4: =_xlfn.XLOOKUP(E4,DATA!$A$5:$A$11,DATA!$O$5:$O$11) -> 0.62120236 | M4: =_xlfn.XLOOKUP(E4,DATA!$A$5:$A$11,DATA!$Q$5:$Q$11) -> 0.72839506 | N4: =_xlfn.XLOOKUP(E4,DATA!$A$5:$A$11,DATA!$S$5:$S$11) -> 1 | O4: =_xlfn.XLOOKUP(E4,DATA!$A$5:$A$11,DATA!$U$5:$U$11) -> 0.086745793 | P4: =_xlfn.XLOOKUP(E4,DATA!$A$5:$A$11,DATA!$W$5:$W$11) -> 1 | Q4: =$C$4*F4+$C$5*G4+$C$6*H4+$C$7*I4+$C$8*J4+$C$9*K4+$C$10*L4+$C$11*M4+$C$12*N4+$C$13*O4+$C$14*P4 -> 0.63958596 | R4: =RANK(Q4,$Q$4:$Q$10,0) -> 2 | S4: =(15-R4)/(15-1) -> 0.92857143 | T4: =IF(S4>80%,"5",IF(S4>60%,"4",IF(S4>40%,"3",IF(S4>20%,"2",IF(S4>=0%,"1"))))) -> 5
A5: 2 | B5: Inflation | C5: 0.07 | E5: India | F5: =_xlfn.XLOOKUP(E5,DATA!$A$4:$A$11,DATA!$C$4:$C$11) -> 1 | G5: =_xlfn.XLOOKUP($E5,DATA!$A$4:$A$11,DATA!$E$4:$E$11) -> 0.90224091 | H5: =_xlfn.XLOOKUP($E5,DATA!$A$4:$A$11,DATA!$G$4:$G$11) -> 0.92149391 | I5: =_xlfn.XLOOKUP(E5,DATA!$A$5:$A$11,DATA!$I$5:$I$11) -> 0.61088906 | J5: =_xlfn.XLOOKUP(E5,DATA!$A$5:$A$11,DATA!$K$5:$K$11) -> 0.35185185 | K5: =_xlfn.XLOOKUP(E5,DATA!$A$5:$A$11,DATA!$M$5:$M$11) -> 0.87721856 | L5: =_xlfn.XLOOKUP(E5,DATA!$A$5:$A$11,DATA!$O$5:$O$11) -> 1 | M5: =_xlfn.XLOOKUP(E5,DATA!$A$5:$A$11,DATA!$Q$5:$Q$11) -> 0.19135803 | N5: =_xlfn.XLOOKUP(E5,DATA!$A$5:$A$11,DATA!$S$5:$S$11) -> 0.91666667 | O5: =_xlfn.XLOOKUP(E5,DATA!$A$5:$A$11,DATA!$U$5:$U$11) -> 1 | P5: =_xlfn.XLOOKUP(E5,DATA!$A$5:$A$11,DATA!$W$5:$W$11) -> 0.26544607 | Q5: =$C$4*F5+$C$5*G5+$C$6*H5+$C$7*I5+$C$8*J5+$C$9*K5+$C$10*L5+$C$11*M5+$C$12*N5+$C$13*O5+$C$14*P5 -> 0.69143718 | R5: =RANK(Q5,$Q$4:$Q$10,0) -> 1 | S5: =(15-R5)/(15-1) -> 1 | T5: =IF(S5>80%,"5",IF(S5>60%,"4",IF(S5>40%,"3",IF(S5>20%,"2",IF(S5>=0%,"1"))))) -> 5
A6: 3 | B6: Gross domestic savings | C6: 0.08 | E6: Bhutan | F6: =_xlfn.XLOOKUP(E6,DATA!$A$4:$A$11,DATA!$C$4:$C$11) -> 0.6882201 | G6: =_xlfn.XLOOKUP($E6,DATA!$A$4:$A$11,DATA!$E$4:$E$11) -> 0.95323823 | H6: =_xlfn.XLOOKUP($E6,DATA!$A$4:$A$11,DATA!$G$4:$G$11) -> 0.55364521 | I6: =_xlfn.XLOOKUP(E6,DATA!$A$5:$A$11,DATA!$I$5:$I$11) -> 0.83385787 | J6: =_xlfn.XLOOKUP(E6,DATA!$A$5:$A$11,DATA!$K$5:$K$11) -> 1 | K6: =_xlfn.XLOOKUP(E6,DATA!$A$5:$A$11,DATA!$M$5:$M$11) -> 0 | L6: =_xlfn.XLOOKUP(E6,DATA!$A$5:$A$11,DATA!$O$5:$O$11) -> 0.42132179 | M6: =_xlfn.XLOOKUP(E6,DATA!$A$5:$A$11,DATA!$Q$5:$Q$11) -> 1 | N6: =_xlfn.XLOOKUP(E6,DATA!$A$5:$A$11,DATA!$S$5:$S$11) -> 1 | O6: =_xlfn.XLOOKUP(E6,DATA!$A$5:$A$11,DATA!$U$5:$U$11) -> 0.18718947 | P6: =_xlfn.XLOOKUP(E6,DATA!$A$5:$A$11,DATA!$W$5:$W$11) -> 0 | Q6: =$C$4*F6+$C$5*G6+$C$6*H6+$C$7*I6+$C$8*J6+$C$9*K6+$C$10*L6+$C$11*M6+$C$12*N6+$C$13*O6+$C$14*P6 -> 0.54538493 | R6: =RANK(Q6,$Q$4:$Q$10,0) -> 3 | S6: =(15-R6)/(15-1) -> 0.85714286 | T6: =IF(S6>80%,"5",IF(S6>60%,"4",IF(S6>40%,"3",IF(S6>20%,"2",IF(S6>=0%,"1"))))) -> 5
A7: 4 | B7: Age dependency ratio | C7: 0.06 | E7: Bangladesh | F7: =_xlfn.XLOOKUP(E7,DATA!$A$4:$A$11,DATA!$C$4:$C$11) -> 0.7733853 | G7: =_xlfn.XLOOKUP($E7,DATA!$A$4:$A$11,DATA!$E$4:$E$11) -> 0.75014827 | H7: =_xlfn.XLOOKUP($E7,DATA!$A$4:$A$11,DATA!$G$4:$G$11) -> 0.77217365 | I7: =_xlfn.XLOOKUP(E7,DATA!$A$5:$A$11,DATA!$I$5:$I$11) -> 0.45040847 | J7: =_xlfn.XLOOKUP(E7,DATA!$A$5:$A$11,DATA!$K$5:$K$11) -> 0 | K7: =_xlfn.XLOOKUP(E7,DATA!$A$5:$A$11,DATA!$M$5:$M$11) -> 0.5045112 | L7: =_xlfn.XLOOKUP(E7,DATA!$A$5:$A$11,DATA!$O$5:$O$11) -> 0.87777086 | M7: =_xlfn.XLOOKUP(E7,DATA!$A$5:$A$11,DATA!$Q$5:$Q$11) -> 0.11728395 | N7: =_xlfn.XLOOKUP(E7,DATA!$A$5:$A$11,DATA!$S$5:$S$11) -> 0.91666667 | O7: =_xlfn.XLOOKUP(E7,DATA!$A$5:$A$11,DATA!$U$5:$U$11) -> 0.70668366 | P7: =_xlfn.XLOOKUP(E7,DATA!$A$5:$A$11,DATA!$W$5:$W$11) -> 0.74439071 | Q7: =$C$4*F7+$C$5*G7+$C$6*H7+$C$7*I7+$C$8*J7+$C$9*K7+$C$10*L7+$C$11*M7+$C$12*N7+$C$13*O7+$C$14*P7 -> 0.5358522 | R7: =RANK(Q7,$Q$4:$Q$10,0) -> 4 | S7: =(15-R7)/(15-1) -> 0.78571429 | T7: =IF(S7>80%,"5",IF(S7>60%,"4",IF(S7>40%,"3",IF(S7>20%,"2",IF(S7>=0%,"1"))))) -> 4
A8: 5 | B8: Control of Corruption | C8: 0.09 | E8: Nepal | F8: =_xlfn.XLOOKUP(E8,DATA!$A$4:$A$11,DATA!$C$4:$C$11) -> 0.41149419 | G8: =_xlfn.XLOOKUP($E8,DATA!$A$4:$A$11,DATA!$E$4:$E$11) -> 0.8495979 | H8: =_xlfn.XLOOKUP($E8,DATA!$A$4:$A$11,DATA!$G$4:$G$11) -> 0.033409405 | I8: =_xlfn.XLOOKUP(E8,DATA!$A$5:$A$11,DATA!$I$5:$I$11) -> 0.42597219 | J8: =_xlfn.XLOOKUP(E8,DATA!$A$5:$A$11,DATA!$K$5:$K$11) -> 0.25308643 | K8: =_xlfn.XLOOKUP(E8,DATA!$A$5:$A$11,DATA!$M$5:$M$11) -> 0.20662526 | L8: =_xlfn.XLOOKUP(E8,DATA!$A$5:$A$11,DATA!$O$5:$O$11) -> 0.52486574 | M8: =_xlfn.XLOOKUP(E8,DATA!$A$5:$A$11,DATA!$Q$5:$Q$11) -> 0.42592594 | N8: =_xlfn.XLOOKUP(E8,DATA!$A$5:$A$11,DATA!$S$5:$S$11) -> 0 | O8: =_xlfn.XLOOKUP(E8,DATA!$A$5:$A$11,DATA!$U$5:$U$11) -> 0 | P8: =_xlfn.XLOOKUP(E8,DATA!$A$5:$A$11,DATA!$W$5:$W$11) -> 0.10692651 | Q8: =$C$4*F8+$C$5*G8+$C$6*H8+$C$7*I8+$C$8*J8+$C$9*K8+$C$10*L8+$C$11*M8+$C$12*N8+$C$13*O8+$C$14*P8 -> 0.2685878 | R8: =RANK(Q8,$Q$4:$Q$10,0) -> 6 | S8: =(15-R8)/(15-1) -> 0.64285714 | T8: =IF(S8>80%,"5",IF(S8>60%,"4",IF(S8>40%,"3",IF(S8>20%,"2",IF(S8>=0%,"1"))))) -> 4
A9: 6 | B9: Employment in industry | C9: 0.1 | E9: Sri Lanka | F9: =_xlfn.XLOOKUP(E9,DATA!$A$4:$A$11,DATA!$C$4:$C$11) -> 0 | G9: =_xlfn.XLOOKUP($E9,DATA!$A$4:$A$11,DATA!$E$4:$E$11) -> 0.51101348 | H9: =_xlfn.XLOOKUP($E9,DATA!$A$4:$A$11,DATA!$G$4:$G$11) -> 0.63937307 | I9: =_xlfn.XLOOKUP(E9,DATA!$A$5:$A$11,DATA!$I$5:$I$11) -> 0.486047 | J9: =_xlfn.XLOOKUP(E9,DATA!$A$5:$A$11,DATA!$K$5:$K$11) -> 0.33333336 | K9: =_xlfn.XLOOKUP(E9,DATA!$A$5:$A$11,DATA!$M$5:$M$11) -> 1 | L9: =_xlfn.XLOOKUP(E9,DATA!$A$5:$A$11,DATA!$O$5:$O$11) -> 0 | M9: =_xlfn.XLOOKUP(E9,DATA!$A$5:$A$11,DATA!$Q$5:$Q$11) -> 0.24691357 | N9: =_xlfn.XLOOKUP(E9,DATA!$A$5:$A$11,DATA!$S$5:$S$11) -> 1 | O9: =_xlfn.XLOOKUP(E9,DATA!$A$5:$A$11,DATA!$U$5:$U$11) -> 0.42693765 | P9: =_xlfn.XLOOKUP(E9,DATA!$A$5:$A$11,DATA!$W$5:$W$11) -> 0.19239255 | Q9: =$C$4*F9+$C$5*G9+$C$6*H9+$C$7*I9+$C$8*J9+$C$9*K9+$C$10*L9+$C$11*M9+$C$12*N9+$C$13*O9+$C$14*P9 -> 0.39677137 | R9: =RANK(Q9,$Q$4:$Q$10,0) -> 5 | S9: =(15-R9)/(15-1) -> 0.71428571 | T9: =IF(S9>80%,"5",IF(S9>60%,"4",IF(S9>40%,"3",IF(S9>20%,"2",IF(S9>=0%,"1"))))) -> 4
A10: 7 | B10: Industry (including construction) | C10: 0.12 | E10: Pakistan | F10: =_xlfn.XLOOKUP(E10,DATA!$A$4:$A$11,DATA!$C$4:$C$11) -> 0.2185155 | G10: =_xlfn.XLOOKUP($E10,DATA!$A$4:$A$11,DATA!$E$4:$E$11) -> 0 | H10: =_xlfn.XLOOKUP($E10,DATA!$A$4:$A$11,DATA!$G$4:$G$11) -> 0 | I10: =_xlfn.XLOOKUP(E10,DATA!$A$5:$A$11,DATA!$I$5:$I$11) -> 0 | J10: =_xlfn.XLOOKUP(E10,DATA!$A$5:$A$11,DATA!$K$5:$K$11) -> 0.055555545 | K10: =_xlfn.XLOOKUP(E10,DATA!$A$5:$A$11,DATA!$M$5:$M$11) -> 0.92774847 | L10: =_xlfn.XLOOKUP(E10,DATA!$A$5:$A$11,DATA!$O$5:$O$11) -> 0.26715288 | M10: =_xlfn.XLOOKUP(E10,DATA!$A$5:$A$11,DATA!$Q$5:$Q$11) -> 0 | N10: =_xlfn.XLOOKUP(E10,DATA!$A$5:$A$11,DATA!$S$5:$S$11) -> 0.26666667 | O10: =_xlfn.XLOOKUP(E10,DATA!$A$5:$A$11,DATA!$U$5:$U$11) -> 0.13015036 | P10: =_xlfn.XLOOKUP(E10,DATA!$A$5:$A$11,DATA!$W$5:$W$11) -> 0.17223022 | Q10: =$C$4*F10+$C$5*G10+$C$6*H10+$C$7*I10+$C$8*J10+$C$9*K10+$C$10*L10+$C$11*M10+$C$12*N10+$C$13*O10+$C$14*P10 -> 0.18682971 | R10: =RANK(Q10,$Q$4:$Q$10,0) -> 7 | S10: =(15-R10)/(15-1) -> 0.57142857 | T10: =IF(S10>80%,"5",IF(S10>60%,"4",IF(S10>40%,"3",IF(S10>20%,"2",IF(S10>=0%,"1"))))) -> 3
A11: 8 | B11: Political Stability and Absence of Violence/Terrorism | C11: 0.09
A12: 9 | B12: Access to electricity | C12: 0.08
A13: 10 | B13: Gross capital formation | C13: 0.1
A14: 11 | B14: Population density (people per sq. km of land area) | C14: 0.03

Sheet DATA
A1: Macroeconomic Performance & Stability Index for South Asian countries (2023)
A3: YEAR | B3: 2023
A4: COUNTRIES | B4: GDP growth (annual %) | C4: GDP growth (annual %) Norm | D4: Inflation, consumer prices (annual %) | E4: Inflation, consumer prices (annual %) Norm | F4: Gross domestic savings (% of GDP) | G4: Gross domestic savings (% of GDP) Norm | H4: Age dependency ratio (% of working-age population) | I4: Age dependency ratio (% of working-age population) (Norm) | J4: Control of Corruption: Percentile Rank | K4: Control of Corruption: Percentile Rank (Norm) | L4: Employment in industry (% of total employment) (modeled ILO estimate) | M4: Employment in industry (% of total employment) (modeled ILO estimate) (Norm) | N4: Industry (including construction), value added (annual % growth) | O4: Industry (including construction), value added (annual % growth) (Norm) | P4: Political Stability and Absence of Violence/Terrorism: Percentile Rank | Q4: Political Stability and Absence of Violence/Terrorism: Percentile Rank (Norm) | R4: Access to electricity (% of population) | S4: Access to electricity (% of population) (Norm) | T4: Gross capital formation (annual % growth) | U4: Gross capital formation (annual % growth) (Norm) | V4: Population density (people per sq. km of land area) | W4: Population density (people per sq. km of land area) (Norm)
A5: India | B5: 8.15 | C5: =(B5-MIN($B$5:$B$11))/(MAX($B$5:$B$11)-MIN($B$5:$B$11)) -> 1 | D5: 5.6491432 | E5: =(MAX($D$5:$D$11)-D5)/(MAX($D$5:$D$11)-MIN($D$5:$D$11)) -> 0.90224091 | F5: 29.506489 | G5: =(F5-MIN($F$5:$F$11))/(MAX($F$5:$F$11)-MIN($F$5:$F$11)) -> 0.92149391 | H5: 47.013218 | I5: =(MAX($H$5:$H$11)-H5)/(MAX($H$5:$H$11)-MIN($H$5:$H$11)) -> 0.61088906 | J5: 41.509434 | K5: =(J5-MIN($J$5:$J$11))/(MAX($J$5:$J$11)-MIN($J$5:$J$11)) -> 0.35185185 | L5: 25.029209 | M5: =(L5-MIN($L$5:$L$11))/(MAX($L$5:$L$11)-MIN($L$5:$L$11)) -> 0.87721856 | N5: 10.818716 | O5: =(N5-MIN($N$5:$N$11))/(MAX($N$5:$N$11)-MIN($N$5:$N$11)) -> 1 | P5: 21.327015 | Q5: =(P5-MIN($P$5:$P$11))/(MAX($P$5:$P$11)-MIN($P$5:$P$11)) -> 0.19135803 | R5: 99.5 | S5: =(R5-MIN($R$5:$R$11))/(MAX($R$5:$R$11)-MIN($R$5:$R$11)) -> 0.91666667 | T5: 10.523698 | U5: =(T5-MIN($T$5:$T$11))/(MAX($T$5:$T$11)-MIN($T$5:$T$11)) -> 1 | V5: 483.67901 | W5: =(V5-MIN($V$5:$V$11))/(MAX($V$5:$V$11)-MIN($V$5:$V$11)) -> 0.26544607
A6: Pakistan | B6: -0.039838972 | C6: =(B6-MIN($B$5:$B$11))/(MAX($B$5:$B$11)-MIN($B$5:$B$11)) -> 0.2185155 | D6: 30.768128 | E6: =(MAX($D$5:$D$11)-D6)/(MAX($D$5:$D$11)-MIN($D$5:$D$11)) -> 0 | F6: 6.3829386 | G6: =(F6-MIN($F$5:$F$11))/(MAX($F$5:$F$11)-MIN($F$5:$F$11)) -> 0 | H6: 70.167386 | I6: =(MAX($H$5:$H$11)-H6)/(MAX($H$5:$H$11)-MIN($H$5:$H$11)) -> 0 | J6: 18.867924 | K6: =(J6-MIN($J$5:$J$11))/(MAX($J$5:$J$11)-MIN($J$5:$J$11)) -> 0.055555545 | L6: 25.592232 | M6: =(L6-MIN($L$5:$L$11))/(MAX($L$5:$L$11)-MIN($L$5:$L$11)) -> 0.92774847 | N6: -3.8788894 | O6: =(N6-MIN($N$5:$N$11))/(MAX($N$5:$N$11)-MIN($N$5:$N$11)) -> 0.26715288 | P6: 6.6350713 | Q6: =(P6-MIN($P$5:$P$11))/(MAX($P$5:$P$11)-MIN($P$5:$P$11)) -> 0 | R6: 95.6 | S6: =(R6-MIN($R$5:$R$11))/(MAX($R$5:$R$11)-MIN($R$5:$R$11)) -> 0.26666667 | T6: -14.128307 | U6: =(T6-MIN($T$5:$T$11))/(MAX($T$5:$T$11)-MIN($T$5:$T$11)) -> 0.13015036 | V6: 321.06747 | W6: =(V6-MIN($V$5:$V$11))/(MAX($V$5:$V$11)-MIN($V$5:$V$11)) -> 0.17223022
A7: Bangladesh | B7: 5.7751124 | C7: =(B7-MIN($B$5:$B$11))/(MAX($B$5:$B$11)-MIN($B$5:$B$11)) -> 0.7733853 | D7: 9.883503 | E7: =(MAX($D$5:$D$11)-D7)/(MAX($D$5:$D$11)-MIN($D$5:$D$11)) -> 0.75014827 | F7: 25.759514 | G7: =(F7-MIN($F$5:$F$11))/(MAX($F$5:$F$11)-MIN($F$5:$F$11)) -> 0.77217365 | H7: 53.095819 | I7: =(MAX($H$5:$H$11)-H7)/(MAX($H$5:$H$11)-MIN($H$5:$H$11)) -> 0.45040847 | J7: 14.622642 | K7: =(J7-MIN($J$5:$J$11))/(MAX($J$5:$J$11)-MIN($J$5:$J$11)) -> 0 | L7: 20.876363 | M7: =(L7-MIN($L$5:$L$11))/(MAX($L$5:$L$11)-MIN($L$5:$L$11)) -> 0.5045112 | N7: 8.3673515 | O7: =(N7-MIN($N$5:$N$11))/(MAX($N$5:$N$11)-MIN($N$5:$N$11)) -> 0.87777086 | P7: 15.639811 | Q7: =(P7-MIN($P$5:$P$11))/(MAX($P$5:$P$11)-MIN($P$5:$P$11)) -> 0.11728395 | R7: 99.5 | S7: =(R7-MIN($R$5:$R$11))/(MAX($R$5:$R$11)-MIN($R$5:$R$11)) -> 0.91666667 | T7: 2.2109556 | U7: =(T7-MIN($T$5:$T$11))/(MAX($T$5:$T$11)-MIN($T$5:$T$11)) -> 0.70668366 | V7: 1319.1798 | W7: =(V7-MIN($V$5:$V$11))/(MAX($V$5:$V$11)-MIN($V$5:$V$11)) -> 0.74439071
A8: Nepal | B8: 1.9825484 | C8: =(B8-MIN($B$5:$B$11))/(MAX($B$5:$B$11)-MIN($B$5:$B$11)) -> 0.41149419 | D8: 7.1147595 | E8: =(MAX($D$5:$D$11)-D8)/(MAX($D$5:$D$11)-MIN($D$5:$D$11)) -> 0.8495979 | F8: 7.2212991 | G8: =(F8-MIN($F$5:$F$11))/(MAX($F$5:$F$11)-MIN($F$5:$F$11)) -> 0.033409405 | H8: 54.022013 | I8: =(MAX($H$5:$H$11)-H8)/(MAX($H$5:$H$11)-MIN($H$5:$H$11)) -> 0.42597219 | J8: 33.962265 | K8: =(J8-MIN($J$5:$J$11))/(MAX($J$5:$J$11)-MIN($J$5:$J$11)) -> 0.25308643 | L8: 17.557205 | M8: =(L8-MIN($L$5:$L$11))/(MAX($L$5:$L$11)-MIN($L$5:$L$11)) -> 0.20662526 | N8: 1.2896675 | O8: =(N8-MIN($N$5:$N$11))/(MAX($N$5:$N$11)-MIN($N$5:$N$11)) -> 0.52486574 | P8: 39.336494 | Q8: =(P8-MIN($P$5:$P$11))/(MAX($P$5:$P$11)-MIN($P$5:$P$11)) -> 0.42592594 | R8: 94 | S8: =(R8-MIN($R$5:$R$11))/(MAX($R$5:$R$11)-MIN($R$5:$R$11)) -> 0 | T8: -17.816837 | U8: =(T8-MIN($T$5:$T$11))/(MAX($T$5:$T$11)-MIN($T$5:$T$11)) -> 0 | V8: 207.14764 | W8: =(V8-MIN($V$5:$V$11))/(MAX($V$5:$V$11)-MIN($V$5:$V$11)) -> 0.10692651
A9: Bhutan | B9: 4.882594 | C9: =(B9-MIN($B$5:$B$11))/(MAX($B$5:$B$11)-MIN($B$5:$B$11)) -> 0.6882201 | D9: 4.2293442 | E9: =(MAX($D$5:$D$11)-D9)/(MAX($D$5:$D$11)-MIN($D$5:$D$11)) -> 0.95323823 | F9: 20.275861 | G9: =(F9-MIN($F$5:$F$11))/(MAX($F$5:$F$11)-MIN($F$5:$F$11)) -> 0.55364521 | H9: 38.562163 | I9: =(MAX($H$5:$H$11)-H9)/(MAX($H$5:$H$11)-MIN($H$5:$H$11)) -> 0.83385787 | J9: 91.037735 | K9: =(J9-MIN($J$5:$J$11))/(MAX($J$5:$J$11)-MIN($J$5:$J$11)) -> 1 | L9: 15.254909 | M9: =(L9-MIN($L$5:$L$11))/(MAX($L$5:$L$11)-MIN($L$5:$L$11)) -> 0 | N9: -0.78695694 | O9: =(N9-MIN($N$5:$N$11))/(MAX($N$5:$N$11)-MIN($N$5:$N$11)) -> 0.42132179 | P9: 83.412323 | Q9: =(P9-MIN($P$5:$P$11))/(MAX($P$5:$P$11)-MIN($P$5:$P$11)) -> 1 | R9: 100 | S9: =(R9-MIN($R$5:$R$11))/(MAX($R$5:$R$11)-MIN($R$5:$R$11)) -> 1 | T9: -12.511788 | U9: =(T9-MIN($T$5:$T$11))/(MAX($T$5:$T$11)-MIN($T$5:$T$11)) -> 0.18718947 | V9: 20.61838 | W9: =(V9-MIN($V$5:$V$11))/(MAX($V$5:$V$11)-MIN($V$5:$V$11)) -> 0
A10: Sri Lanka | B10: -2.3298482 | C10: =(B10-MIN($B$5:$B$11))/(MAX($B$5:$B$11)-MIN($B$5:$B$11)) -> 0 | D10: 16.541174 | E10: =(MAX($D$5:$D$11)-D10)/(MAX($D$5:$D$11)-MIN($D$5:$D$11)) -> 0.51101348 | F10: 22.427076 | G10: =(F10-MIN($F$5:$F$11))/(MAX($F$5:$F$11)-MIN($F$5:$F$11)) -> 0.63937307 | H10: 51.745033 | I10: =(MAX($H$5:$H$11)-H10)/(MAX($H$5:$H$11)-MIN($H$5:$H$11)) -> 0.486047 | J10: 40.094341 | K10: =(J10-MIN($J$5:$J$11))/(MAX($J$5:$J$11)-MIN($J$5:$J$11)) -> 0.33333336 | L10: 26.397286 | M10: =(L10-MIN($L$5:$L$11))/(MAX($L$5:$L$11)-MIN($L$5:$L$11)) -> 1 | N10: -9.2367704 | O10: =(N10-MIN($N$5:$N$11))/(MAX($N$5:$N$11)-MIN($N$5:$N$11)) -> 0 | P10: 25.592417 | Q10: =(P10-MIN($P$5:$P$11))/(MAX($P$5:$P$11)-MIN($P$5:$P$11)) -> 0.24691357 | R10: 100 | S10: =(R10-MIN($R$5:$R$11))/(MAX($R$5:$R$11)-MIN($R$5:$R$11)) -> 1 | T10: -5.7171961 | U10: =(T10-MIN($T$5:$T$11))/(MAX($T$5:$T$11)-MIN($T$5:$T$11)) -> 0.42693765 | V10: 356.2399 | W10: =(V10-MIN($V$5:$V$11))/(MAX($V$5:$V$11)-MIN($V$5:$V$11)) -> 0.19239255
A11: Maldives | B11: 4.726392 | C11: =(B11-MIN($B$5:$B$11))/(MAX($B$5:$B$11)-MIN($B$5:$B$11)) -> 0.67331511 | D11: 2.9274654 | E11: =(MAX($D$5:$D$11)-D11)/(MAX($D$5:$D$11)-MIN($D$5:$D$11)) -> 1 | F11: 31.476485 | G11: =(F11-MIN($F$5:$F$11))/(MAX($F$5:$F$11)-MIN($F$5:$F$11)) -> 1 | H11: 32.264976 | I11: =(MAX($H$5:$H$11)-H11)/(MAX($H$5:$H$11)-MIN($H$5:$H$11)) -> 1 | J11: 39.622643 | K11: =(J11-MIN($J$5:$J$11))/(MAX($J$5:$J$11)-MIN($J$5:$J$11)) -> 0.32716051 | L11: 25.004699 | M11: =(L11-MIN($L$5:$L$11))/(MAX($L$5:$L$11)-MIN($L$5:$L$11)) -> 0.87501887 | N11: 3.2217453 | O11: =(N11-MIN($N$5:$N$11))/(MAX($N$5:$N$11)-MIN($N$5:$N$11)) -> 0.62120236 | P11: 62.559242 | Q11: =(P11-MIN($P$5:$P$11))/(MAX($P$5:$P$11)-MIN($P$5:$P$11)) -> 0.72839506 | R11: 100 | S11: =(R11-MIN($R$5:$R$11))/(MAX($R$5:$R$11)-MIN($R$5:$R$11)) -> 1 | T11: -15.358415 | U11: =(T11-MIN($T$5:$T$11))/(MAX($T$5:$T$11)-MIN($T$5:$T$11)) -> 0.086745793 | V11: 1765.0805 | W11: =(V11-MIN($V$5:$V$11))/(MAX($V$5:$V$11)-MIN($V$5:$V$11)) -> 1

Sheet RAW DATA AND SOURCES
A1: Country Name | B1: Country Code | C1: Series Name | D1: Series Code | E1: 2023 [YR2023]
A2: India | B2: IND | C2: Unemployment, total (% of total labor force) (national estimate) | D2: SL.UEM.TOTL.NE.ZS | E2: 4.172
A3: India | B3: IND | C3: Age dependency ratio (% of working-age population) | D3: SP.POP.DPND | E3: 47.013218
A4: India | B4: IND | C4: Central government debt, total (% of GDP) | D4: GC.DOD.TOTL.GD.ZS | E4: ..
A5: India | B5: IND | C5: Industry (including construction), value added (annual % growth) | D5: NV.IND.TOTL.KD.ZG | E5: 10.818716
A6: India | B6: IND | C6: Employment in industry (% of total employment) (modeled ILO estimate) | D6: SL.IND.EMPL.ZS | E6: 25.029209
A7: India | B7: IND | C7: Control of Corruption: Percentile Rank | D7: CC.PER.RNK | E7: 41.509434
A8: India | B8: IND | C8: Political Stability and Absence of Violence/Terrorism: Percentile Rank | D8: PV.PER.RNK | E8: 21.327015
A9: India | B9: IND | C9: Proportion of people living below 50 percent of median income (%) | D9: SI.DST.50MD | E9: ..
A10: India | B10: IND | C10: Research and development expenditure (% of GDP) | D10: GB.XPD.RSDV.GD.ZS | E10: ..
A11: India | B11: IND | C11: Real interest rate (%) | D11: FR.INR.RINR | E11: ..
A12: India | B12: IND | C12: Lending interest rate (%) | D12: FR.INR.LEND | E12: ..
A13: Maldives | B13: MDV | C13: Unemployment, total (% of total labor force) (national estimate) | D13: SL.UEM.TOTL.NE.ZS | E13: ..
A14: Maldives | B14: MDV | C14: Age dependency ratio (% of working-age population) | D14: SP.POP.DPND | E14: 32.264976
A15: Maldives | B15: MDV | C15: Central government debt, total (% of GDP) | D15: GC.DOD.TOTL.GD.ZS | E15: ..
A16: Maldives | B16: MDV | C16: Industry (including construction), value added (annual % growth) | D16: NV.IND.TOTL.KD.ZG | E16: 3.2217453
A17: Maldives | B17: MDV | C17: Employment in industry (% of total employment) (modeled ILO estimate) | D17: SL.IND.EMPL.ZS | E17: 25.004699
A18: Maldives | B18: MDV | C18: Control of Corruption: Percentile Rank | D18: CC.PER.RNK | E18: 39.622643
A19: Maldives | B19: MDV | C19: Political Stability and Absence of Violence/Terrorism: Percentile Rank | D19: PV.PER.RNK | E19: 62.559242
A20: Maldives | B20: MDV | C20: Proportion of people living below 50 percent of median income (%) | D20: SI.DST.50MD | E20: ..
A21: Maldives | B21: MDV | C21: Research and development expenditure (% of GDP) | D21: GB.XPD.RSDV.GD.ZS | E21: ..
A22: Maldives | B22: MDV | C22: Real interest rate (%) | D22: FR.INR.RINR | E22: 9.3434577
A23: Maldives | B23: MDV | C23: Lending interest rate (%) | D23: FR.INR.LEND | E23: 11.681837
A24: Bhutan | B24: BTN | C24: Unemployment, total (% of total labor force) (national estimate) | D24: SL.UEM.TOTL.NE.ZS | E24: 3.126
A25: Bhutan | B25: BTN | C25: Age dependency ratio (% of working-age population) | D25: SP.POP.DPND | E25: 38.562163
A26: Bhutan | B26: BTN | C26: Central government debt, total (% of GDP) | D26: GC.DOD.TOTL.GD.ZS | E26: ..
A27: Bhutan | B27: BTN | C27: Industry (including construction), value added (annual % growth) | D27: NV.IND.TOTL.KD.ZG | E27: -0.78695694
A28: Bhutan | B28: BTN | C28: Employment in industry (% of total employment) (modeled ILO estimate) | D28: SL.IND.EMPL.ZS | E28: 15.254909
A29: Bhutan | B29: BTN | C29: Control of Corruption: Percentile Rank | D29: CC.PER.RNK | E29: 91.037735
A30: Bhutan | B30: BTN | C30: Political Stability and Absence of Violence/Terrorism: Percentile Rank | D30: PV.PER.RNK | E30: 83.412323
A31: Bhutan | B31: BTN | C31: Proportion of people living below 50 percent of median income (%) | D31: SI.DST.50MD | E31: ..
A32: Bhutan | B32: BTN | C32: Research and development expenditure (% of GDP) | D32: GB.XPD.RSDV.GD.ZS | E32: ..
A33: Bhutan | B33: BTN | C33: Real interest rate (%) | D33: FR.INR.RINR | E33: 7.5346127
A34: Bhutan | B34: BTN | C34: Lending interest rate (%) | D34: FR.INR.LEND | E34: 12.27
A35: Bangladesh | B35: BGD | C35: Unemployment, total (% of total labor force) (national estimate) | D35: SL.UEM.TOTL.NE.ZS | E35: 3.352
A36: Bangladesh | B36: BGD | C36: Age dependency ratio (% of working-age population) | D36: SP.POP.DPND | E36: 53.095819
A37: Bangladesh | B37: BGD | C37: Central government debt, total (% of GDP) | D37: GC.DOD.TOTL.GD.ZS | E37: ..
A38: Bangladesh | B38: BGD | C38: Industry (including construction), value added (annual % growth) | D38: NV.IND.TOTL.KD.ZG | E38: 8.3673515
A39: Bangladesh | B39: BGD | C39: Employment in industry (% of total employment) (modeled ILO estimate) | D39: SL.IND.EMPL.ZS | E39: 20.876363
A40: Bangladesh | B40: BGD | C40: Control of Corruption: Percentile Rank | D40: CC.PER.RNK | E40: 14.622642
...

Sheet India
A1: Country | B1: Company | C1: Sector Name | D1: Architecture | E1: Annual Report
A2: India | B2: Larsen and Toubro Ltd | C2: Industrials | D2: Construction & Engineering (EPC), Heavy Engineering, Defence Manufacturing, Smart Infrastructure, Renewable & Digital Engineering Solutions | E2: https://investors.larsentoubro.com/upload/AnnualRep/FY2025AnnualRepL&T-ANNUAL%20REPORT%202024-25%20-%20LOW%202.pdf
A3: India | B3: Adani Ports and Special Economic Zone Ltd | C3: Industrials | D3: Port infrastructure and integrated logistics architecture with leadership in multi-cargo port operations, SEZ-linked industrial logistics, automated port handling systems, and end-to-end supply chain infrastructure | E3: https://www.adaniports.com/-/media/Project/Ports/Investor/Investor-Downloads/Annual-Report/FY24.pdf
A4: Bangladesh | B4: Bangladesh Export Import Company Ltd | C4: Industrials | D4: Diversified industrial and manufacturing architecture with leadership in pharmaceuticals manufacturing, textiles, ceramics, and industrial trading, supported by vertically integrated production and export-oriented operations | E4: https://www.beximco.com/storage/app/media/Reports/AR_BEXIMCO_2023-24.pdf
A5: Bangladesh | B5: Advanced Chemical Industries Plc | C5: Industrials | D5: Chemical and agro-industrial architecture with leadership in crop protection chemicals, pharmaceuticals, consumer chemicals, and agribusiness solutions, supported by formulation technology and distribution-driven industrial capabilities | E5: NA

Sheet Top Companies in Industrials
A1: =_xll.TR("SCREEN(U(IN(Equity(active,public,primary))/*UNV:Public*/), IN(TR.HQCountryCode,""IN"",""MV""), IN(TR.GICSSectorCode,""20""), TOP(TR.CompanyMarketCap(Scale=6), 10, nnumber), CURN=USD)","TR.CommonName;TR.HeadquartersCountry;TR.GICSSector;TR.Compan"&"yMarketCap(Scale=6)","curn=USD RH=In CH=Fd") -> Not Signed In | B1: Company Common Name | C1: Country of Headquarters | D1: GICS Sector Name | E1: Company Market Cap
A2: LART.NS | B2: Larsen and Toubro Ltd | C2: India | D2: Industrials | E2: 62158.138
A3: APSE.NS | B3: Adani Ports and Special Economic Zone Ltd | C3: India | D3: Industrials | E3: 36078.642
A4: HIAE.NS | B4: Hindustan Aeronautics Ltd | C4: India | D4: Industrials | E4: 31913.101
A5: BAJE.NS | B5: Bharat Electronics Ltd | C5: India | D5: Industrials | E5: 31538.979
A6: ADEL.NS | B6: Adani Enterprises Ltd | C6: India | D6: Industrials | E6: 29043.135
A7: INGL.NS | B7: Interglobe Aviation Ltd | C7: India | D7: Industrials | E7: 21196.233
A8: TATM.NS | B8: Tata Motors Ltd | C8: India | D8: Industrials | E8: 15367.443
A9: CUMM.NS | B9: Cummins India Ltd | C9: India | D9: Industrials | E9: 13895.812
A10: SIEM.NS | B10: Siemens Ltd | C10: India | D10: Industrials | E10: 12417.267
A11: ABB.NS | B11: ABB India Ltd | C11: India | D11: Industrials | E11: 12366.236

Sheet Industrials (Bangladesh)
A1: =_xll.TR("SCREEN(U(IN(Equity(active,public,primary))/*UNV:Public*/), IN(TR.HQCountryCode,""BD""), IN(TR.GICSSectorCode,""20""), TOP(TR.CompanyMarketCap(Scale=6), 10, nnumber), CURN=USD)","TR.CommonName;TR.HeadquartersCountry;TR.GICSSector;TR.CompanyMarket"&"Cap(Scale=6)","curn=USD RH=In CH=Fd") -> Not Signed In | B1: Company Common Name | C1: Country of Headquarters | D1: GICS Sector Name | E1: Company Market Cap
A2: BEXI.DH | B2: Bangladesh Export Import Company Ltd | C2: Bangladesh | D2: Industrials | E2: 853.33004
A3: ACLT.DH | B3: Advanced Chemical Industries Plc | C3: Bangladesh | D3: Industrials | E3: 141.50013
A4: BSCD.DH | B4: Bangladesh Shipping Corp | C4: Bangladesh | D4: Industrials | E4: 131.10243
A5: SAPO.DH | B5: Summit Alliance Port Ltd | C5: Bangladesh | D5: Industrials | E5: 79.215217
A6: RAKC.DH | B6: Rak Ceramics (Bangladesh) Ltd | C6: Bangladesh | D6: Industrials | E6: 78.419902
A7: GQBP.DH | B7: GQ Ball Pen Industries Ltd | C7: Bangladesh | D7: Industrials | E7: 32.293719
A8: MIRA.DH | B8: Mir Akhter Hossain Ltd | C8: Bangladesh | D8: Industrials | E8: 27.786387
A9: QASE.DH | B9: Quasem Industries Ltd | C9: Bangladesh | D9: Industrials | E9: 27.082718
A10: BBSC.DH | B10: BBS Cables PLC | C10: Bangladesh | D10: Industrials | E10: 26.268015
A11: ENCS.DH | B11: Eastern Cables Ltd | C11: Bangladesh | D11: Industrials | E11: 24.924897
